<?xml version="1.0" ?>
<robot name="spider_robot" xmlns:xacro="http://www.ros.org/wiki/xacro">

<xacro:include filename="$(find spider_robot_description)/urdf/materials.xacro" />
<xacro:include filename="$(find spider_robot_description)/urdf/spider_robot.trans" />
<xacro:include filename="$(find spider_robot_description)/urdf/spider_robot.gazebo" />

<link name="dummy">
</link>

<joint name="dummy_joint" type="fixed">
  <parent link="dummy"/>
  <child link="base_link"/>
</joint>

<link name="base_link">
  <inertial>
    <origin xyz="0.0021738035282516323 -5.3831472792831295e-06 0.01261348241836993" rpy="0 0 0"/>
    <mass value="1.3309040257890745"/>
    <inertia ixx="0.002367" iyy="0.004807" izz="0.006796" ixy="-1e-06" iyz="0.0" ixz="-0.000181"/>
  </inertial>
  <visual>
    <origin xyz="0 0 0" rpy="0 0 0"/>
    <geometry>
      <mesh filename="package://spider_robot_description/meshes/base_link.stl" scale="0.001 0.001 0.001"/>
    </geometry>
    <material name="_"/>
  </visual>
  <collision>
    <origin xyz="0 0 0" rpy="0 0 0"/>
    <geometry>
      <mesh filename="package://spider_robot_description/meshes/base_link.stl" scale="0.001 0.001 0.001"/>
    </geometry>
  </collision>
</link>

<link name="part1_1">
  <inertial>
    <origin xyz="0.022505274993332033 0.02250533409144543 0.025822431167356885" rpy="0 0 0"/>
    <mass value="0.4602344613336842"/>
    <inertia ixx="0.000191" iyy="0.000191" izz="0.000233" ixy="-1.7e-05" iyz="2e-06" ixz="2e-06"/>
  </inertial>
  <visual>
    <origin xyz="-0.095 -0.0545 -0.005" rpy="0 0 0"/>
    <geometry>
      <mesh filename="package://spider_robot_description/meshes/part1_1.stl" scale="0.001 0.001 0.001"/>
    </geometry>
    <material name="_"/>
  </visual>
  <collision>
    <origin xyz="-0.095 -0.0545 -0.005" rpy="0 0 0"/>
    <geometry>
      <mesh filename="package://spider_robot_description/meshes/part1_1.stl" scale="0.001 0.001 0.001"/>
    </geometry>
  </collision>
</link>

<link name="part2_1">
  <inertial>
    <origin xyz="0.0700858828860957 -0.01258371206185141 7.509815979495071e-08" rpy="0 0 0"/>
    <mass value="0.4914048488278606"/>
    <inertia ixx="0.000667" iyy="0.000662" izz="0.001296" ixy="0.000141" iyz="-0.0" ixz="0.0"/>
  </inertial>
  <visual>
    <origin xyz="-0.12058 -0.116673 -0.0304" rpy="0 0 0"/>
    <geometry>
      <mesh filename="package://spider_robot_description/meshes/part2_1.stl" scale="0.001 0.001 0.001"/>
    </geometry>
    <material name="_"/>
  </visual>
  <collision>
    <origin xyz="-0.12058 -0.116673 -0.0304" rpy="0 0 0"/>
    <geometry>
      <mesh filename="package://spider_robot_description/meshes/part2_1.stl" scale="0.001 0.001 0.001"/>
    </geometry>
  </collision>
</link>

<link name="part4_1">
  <inertial>
    <origin xyz="0.02250533409144241 -0.02250527499333315 0.02582243116735693" rpy="0 0 0"/>
    <mass value="0.4602344613336842"/>
    <inertia ixx="0.000191" iyy="0.000191" izz="0.000233" ixy="1.7e-05" iyz="-2e-06" ixz="2e-06"/>
  </inertial>
  <visual>
    <origin xyz="-0.095 0.0545 -0.005" rpy="0 0 0"/>
    <geometry>
      <mesh filename="package://spider_robot_description/meshes/part4_1.stl" scale="0.001 0.001 0.001"/>
    </geometry>
    <material name="_"/>
  </visual>
  <collision>
    <origin xyz="-0.095 0.0545 -0.005" rpy="0 0 0"/>
    <geometry>
      <mesh filename="package://spider_robot_description/meshes/part4_1.stl" scale="0.001 0.001 0.001"/>
    </geometry>
  </collision>
</link>

<link name="part5_1">
  <inertial>
    <origin xyz="0.07008588288609359 0.012583712061850896 -7.509815944453657e-08" rpy="0 0 0"/>
    <mass value="0.4914048488278606"/>
    <inertia ixx="0.000667" iyy="0.000662" izz="0.001296" ixy="-0.000141" iyz="-0.0" ixz="-0.0"/>
  </inertial>
  <visual>
    <origin xyz="-0.12058 0.116673 -0.0304" rpy="0 0 0"/>
    <geometry>
      <mesh filename="package://spider_robot_description/meshes/part5_1.stl" scale="0.001 0.001 0.001"/>
    </geometry>
    <material name="_"/>
  </visual>
  <collision>
    <origin xyz="-0.12058 0.116673 -0.0304" rpy="0 0 0"/>
    <geometry>
      <mesh filename="package://spider_robot_description/meshes/part5_1.stl" scale="0.001 0.001 0.001"/>
    </geometry>
  </collision>
</link>

<link name="part7_1">
  <inertial>
    <origin xyz="-4.1788675663946726e-08 0.03182730690918333 0.025822431167356972" rpy="0 0 0"/>
    <mass value="0.4602344613336842"/>
    <inertia ixx="0.000208" iyy="0.000175" izz="0.000233" ixy="-0.0" iyz="3e-06" ixz="0.0"/>
  </inertial>
  <visual>
    <origin xyz="-0.0 -0.0545 -0.005" rpy="0 0 0"/>
    <geometry>
      <mesh filename="package://spider_robot_description/meshes/part7_1.stl" scale="0.001 0.001 0.001"/>
    </geometry>
    <material name="_"/>
  </visual>
  <collision>
    <origin xyz="-0.0 -0.0545 -0.005" rpy="0 0 0"/>
    <geometry>
      <mesh filename="package://spider_robot_description/meshes/part7_1.stl" scale="0.001 0.001 0.001"/>
    </geometry>
  </collision>
</link>

<link name="part8_1">
  <inertial>
    <origin xyz="0.0584560727416802 0.04065991629223413 7.509815936820874e-08" rpy="0 0 0"/>
    <mass value="0.4914048488278607"/>
    <inertia ixx="0.000523" iyy="0.000806" izz="0.001296" ixy="3e-06" iyz="-0.0" ixz="0.0"/>
  </inertial>
  <visual>
    <origin xyz="0.025875 -0.116551 -0.0304" rpy="0 0 0"/>
    <geometry>
      <mesh filename="package://spider_robot_description/meshes/part8_1.stl" scale="0.001 0.001 0.001"/>
    </geometry>
    <material name="_"/>
  </visual>
  <collision>
    <origin xyz="0.025875 -0.116551 -0.0304" rpy="0 0 0"/>
    <geometry>
      <mesh filename="package://spider_robot_description/meshes/part8_1.stl" scale="0.001 0.001 0.001"/>
    </geometry>
  </collision>
</link>

<link name="part10_1">
  <inertial>
    <origin xyz="4.178867428557693e-08 -0.03182730690918042 0.025822431167356934" rpy="0 0 0"/>
    <mass value="0.4602344613336842"/>
    <inertia ixx="0.000208" iyy="0.000175" izz="0.000233" ixy="-0.0" iyz="-3e-06" ixz="-0.0"/>
  </inertial>
  <visual>
    <origin xyz="0.0 0.0545 -0.005" rpy="0 0 0"/>
    <geometry>
      <mesh filename="package://spider_robot_description/meshes/part10_1.stl" scale="0.001 0.001 0.001"/>
    </geometry>
    <material name="_"/>
  </visual>
  <collision>
    <origin xyz="0.0 0.0545 -0.005" rpy="0 0 0"/>
    <geometry>
      <mesh filename="package://spider_robot_description/meshes/part10_1.stl" scale="0.001 0.001 0.001"/>
    </geometry>
  </collision>
</link>

<link name="part11_1">
  <inertial>
    <origin xyz="0.05845607274167791 -0.04065991629223088 -7.509816075945697e-08" rpy="0 0 0"/>
    <mass value="0.4914048488278607"/>
    <inertia ixx="0.000523" iyy="0.000806" izz="0.001296" ixy="-3e-06" iyz="-0.0" ixz="-0.0"/>
  </inertial>
  <visual>
    <origin xyz="0.025875 0.116551 -0.0304" rpy="0 0 0"/>
    <geometry>
      <mesh filename="package://spider_robot_description/meshes/part11_1.stl" scale="0.001 0.001 0.001"/>
    </geometry>
    <material name="_"/>
  </visual>
  <collision>
    <origin xyz="0.025875 0.116551 -0.0304" rpy="0 0 0"/>
    <geometry>
      <mesh filename="package://spider_robot_description/meshes/part11_1.stl" scale="0.001 0.001 0.001"/>
    </geometry>
  </collision>
</link>

<link name="part13_1">
  <inertial>
    <origin xyz="-0.022505334091443813 0.02250527499333347 0.02582243116735773" rpy="0 0 0"/>
    <mass value="0.4602344613336842"/>
    <inertia ixx="0.000191" iyy="0.000191" izz="0.000233" ixy="1.7e-05" iyz="2e-06" ixz="-2e-06"/>
  </inertial>
  <visual>
    <origin xyz="0.095 -0.0545 -0.005" rpy="0 0 0"/>
    <geometry>
      <mesh filename="package://spider_robot_description/meshes/part13_1.stl" scale="0.001 0.001 0.001"/>
    </geometry>
    <material name="_"/>
  </visual>
  <collision>
    <origin xyz="0.095 -0.0545 -0.005" rpy="0 0 0"/>
    <geometry>
      <mesh filename="package://spider_robot_description/meshes/part13_1.stl" scale="0.001 0.001 0.001"/>
    </geometry>
  </collision>
</link>

<link name="part14_1">
  <inertial>
    <origin xyz="-0.03416463432822242 0.023337536496022104 7.509816054088181e-08" rpy="0 0 0"/>
    <mass value="0.4914048488278606"/>
    <inertia ixx="0.000662" iyy="0.000667" izz="0.001296" ixy="-0.000141" iyz="-0.0" ixz="-0.0"/>
  </inertial>
  <visual>
    <origin xyz="0.157173 -0.08008 -0.0304" rpy="0 0 0"/>
    <geometry>
      <mesh filename="package://spider_robot_description/meshes/part14_1.stl" scale="0.001 0.001 0.001"/>
    </geometry>
    <material name="_"/>
  </visual>
  <collision>
    <origin xyz="0.157173 -0.08008 -0.0304" rpy="0 0 0"/>
    <geometry>
      <mesh filename="package://spider_robot_description/meshes/part14_1.stl" scale="0.001 0.001 0.001"/>
    </geometry>
  </collision>
</link>

<link name="part16_1">
  <inertial>
    <origin xyz="-0.022505274993333407 -0.022505334091439795 0.025822431167357933" rpy="0 0 0"/>
    <mass value="0.4602344613336841"/>
    <inertia ixx="0.000191" iyy="0.000191" izz="0.000233" ixy="-1.7e-05" iyz="-2e-06" ixz="-2e-06"/>
  </inertial>
  <visual>
    <origin xyz="0.095 0.0545 -0.005" rpy="0 0 0"/>
    <geometry>
      <mesh filename="package://spider_robot_description/meshes/part16_1.stl" scale="0.001 0.001 0.001"/>
    </geometry>
    <material name="_"/>
  </visual>
  <collision>
    <origin xyz="0.095 0.0545 -0.005" rpy="0 0 0"/>
    <geometry>
      <mesh filename="package://spider_robot_description/meshes/part16_1.stl" scale="0.001 0.001 0.001"/>
    </geometry>
  </collision>
</link>

<link name="part17_1">
  <inertial>
    <origin xyz="-0.03416463432822456 -0.023337536496015623 -7.509815899350847e-08" rpy="0 0 0"/>
    <mass value="0.4914048488278606"/>
    <inertia ixx="0.000662" iyy="0.000667" izz="0.001296" ixy="0.000141" iyz="-0.0" ixz="0.0"/>
  </inertial>
  <visual>
    <origin xyz="0.157173 0.08008 -0.0304" rpy="0 0 0"/>
    <geometry>
      <mesh filename="package://spider_robot_description/meshes/part17_1.stl" scale="0.001 0.001 0.001"/>
    </geometry>
    <material name="_"/>
  </visual>
  <collision>
    <origin xyz="0.157173 0.08008 -0.0304" rpy="0 0 0"/>
    <geometry>
      <mesh filename="package://spider_robot_description/meshes/part17_1.stl" scale="0.001 0.001 0.001"/>
    </geometry>
  </collision>
</link>

<link name="part3_1">
  <inertial>
    <origin xyz="0.004221158383464624 -0.04758074361356199 -0.010298255954450997" rpy="0 0 0"/>
    <mass value="0.12505650813052724"/>
    <inertia ixx="0.001082" iyy="0.000159" izz="0.001129" ixy="-7.5e-05" iyz="-0.000208" ixz="-1.1e-05"/>
  </inertial>
  <visual>
    <origin xyz="-0.214003 -0.138254 -0.0304" rpy="0 0 0"/>
    <geometry>
      <mesh filename="package://spider_robot_description/meshes/part3_1.stl" scale="0.001 0.001 0.001"/>
    </geometry>
    <material name="_"/>
  </visual>
  <collision>
    <origin xyz="-0.214003 -0.138254 -0.0304" rpy="0 0 0"/>
    <geometry>
      <mesh filename="package://spider_robot_description/meshes/part3_1.stl" scale="0.001 0.001 0.001"/>
    </geometry>
  </collision>
</link>

<link name="part6_1">
  <inertial>
    <origin xyz="0.03479869953680867 0.0592049589644737 -0.010298255954450442" rpy="0 0 0"/>
    <mass value="0.1250565081305319"/>
    <inertia ixx="0.001363" iyy="0.000216" izz="0.001467" ixy="-0.000277" iyz="0.000239" ixz="6.3e-05"/>
  </inertial>
  <visual>
    <origin xyz="-0.214003 0.138254 -0.0304" rpy="0 0 0"/>
    <geometry>
      <mesh filename="package://spider_robot_description/meshes/part6_1.stl" scale="0.001 0.001 0.001"/>
    </geometry>
    <material name="_"/>
  </visual>
  <collision>
    <origin xyz="-0.214003 0.138254 -0.0304" rpy="0 0 0"/>
    <geometry>
      <mesh filename="package://spider_robot_description/meshes/part6_1.stl" scale="0.001 0.001 0.001"/>
    </geometry>
  </collision>
</link>

<link name="part9_1">
  <inertial>
    <origin xyz="-0.029793763473125137 0.04613844978067949 -0.010298255954450313" rpy="0 0 0"/>
    <mass value="0.12505650813053223"/>
    <inertia ixx="0.000196" iyy="0.000106" izz="0.000191" ixy="-8e-06" iyz="2e-05" ixz="-1.2e-05"/>
  </inertial>
  <visual>
    <origin xyz="-0.024925 -0.197871 -0.0304" rpy="0 0 0"/>
    <geometry>
      <mesh filename="package://spider_robot_description/meshes/part9_1.stl" scale="0.001 0.001 0.001"/>
    </geometry>
    <material name="_"/>
  </visual>
  <collision>
    <origin xyz="-0.024925 -0.197871 -0.0304" rpy="0 0 0"/>
    <geometry>
      <mesh filename="package://spider_robot_description/meshes/part9_1.stl" scale="0.001 0.001 0.001"/>
    </geometry>
  </collision>
</link>

<link name="part12_1">
  <inertial>
    <origin xyz="-0.0763301129730041 -0.06509177558310722 -0.010298255954450247" rpy="0 0 0"/>
    <mass value="0.12505650813053235"/>
    <inertia ixx="0.000278" iyy="0.000392" izz="0.000557" ixy="-0.000175" iyz="-6.3e-05" ixz="-0.000111"/>
  </inertial>
  <visual>
    <origin xyz="-0.024925 0.197871 -0.0304" rpy="0 0 0"/>
    <geometry>
      <mesh filename="package://spider_robot_description/meshes/part12_1.stl" scale="0.001 0.001 0.001"/>
    </geometry>
    <material name="_"/>
  </visual>
  <collision>
    <origin xyz="-0.024925 0.197871 -0.0304" rpy="0 0 0"/>
    <geometry>
      <mesh filename="package://spider_robot_description/meshes/part12_1.stl" scale="0.001 0.001 0.001"/>
    </geometry>
  </collision>
</link>

<link name="part15_1">
  <inertial>
    <origin xyz="-0.03721261981245194 0.07321669362063984 -0.010298255954450782" rpy="0 0 0"/>
    <mass value="0.12505650813052843"/>
    <inertia ixx="0.000643" iyy="0.000138" izz="0.00067" ixy="-1.1e-05" iyz="0.000146" ixz="1.5e-05"/>
  </inertial>
  <visual>
    <origin xyz="0.178754 -0.173503 -0.0304" rpy="0 0 0"/>
    <geometry>
      <mesh filename="package://spider_robot_description/meshes/part15_1.stl" scale="0.001 0.001 0.001"/>
    </geometry>
    <material name="_"/>
  </visual>
  <collision>
    <origin xyz="0.178754 -0.173503 -0.0304" rpy="0 0 0"/>
    <geometry>
      <mesh filename="package://spider_robot_description/meshes/part15_1.stl" scale="0.001 0.001 0.001"/>
    </geometry>
  </collision>
</link>

<link name="part18_1">
  <inertial>
    <origin xyz="-0.08233230187734139 0.09080916411778589 -0.010298255954450788" rpy="0 0 0"/>
    <mass value="0.12505650813052913"/>
    <inertia ixx="0.001224" iyy="0.000322" izz="0.001434" ixy="0.000383" iyz="0.000223" ixz="-8.3e-05"/>
  </inertial>
  <visual>
    <origin xyz="0.178754 0.173503 -0.0304" rpy="0 0 0"/>
    <geometry>
      <mesh filename="package://spider_robot_description/meshes/part18_1.stl" scale="0.001 0.001 0.001"/>
    </geometry>
    <material name="_"/>
  </visual>
  <collision>
    <origin xyz="0.178754 0.173503 -0.0304" rpy="0 0 0"/>
    <geometry>
      <mesh filename="package://spider_robot_description/meshes/part18_1.stl" scale="0.001 0.001 0.001"/>
    </geometry>
  </collision>
</link>

<link name="d_part1_1">
  <inertial>
    <origin xyz="-2.5494084521238136e-07 2.479434127455882e-07 -2.3314683517128287e-15" rpy="0 0 0"/>
    <mass value="4.110250388446646e-06"/>
    <inertia ixx="0.0" iyy="0.0" izz="0.0" ixy="0.0" iyz="-0.0" ixz="0.0"/>
  </inertial>
  <visual>
    <origin xyz="-0.294702 -0.255545 -0.0304" rpy="0 0 0"/>
    <geometry>
      <mesh filename="package://spider_robot_description/meshes/d_part1_1.stl" scale="0.001 0.001 0.001"/>
    </geometry>
    <material name="_"/>
  </visual>
  <collision>
    <origin xyz="-0.294702 -0.255545 -0.0304" rpy="0 0 0"/>
    <geometry>
      <mesh filename="package://spider_robot_description/meshes/d_part1_1.stl" scale="0.001 0.001 0.001"/>
    </geometry>
  </collision>
</link>

<link name="d_part2_1">
  <inertial>
    <origin xyz="-2.5494084521238136e-07 2.479434127455882e-07 -2.3314683517128287e-15" rpy="0 0 0"/>
    <mass value="4.110250388446646e-06"/>
    <inertia ixx="0.0" iyy="0.0" izz="0.0" ixy="0.0" iyz="-0.0" ixz="0.0"/>
  </inertial>
  <visual>
    <origin xyz="-0.294702 -0.255545 -0.0304" rpy="0 0 0"/>
    <geometry>
      <mesh filename="package://spider_robot_description/meshes/d_part2_1.stl" scale="0.001 0.001 0.001"/>
    </geometry>
    <material name="_"/>
  </visual>
  <collision>
    <origin xyz="-0.294702 -0.255545 -0.0304" rpy="0 0 0"/>
    <geometry>
      <mesh filename="package://spider_robot_description/meshes/d_part2_1.stl" scale="0.001 0.001 0.001"/>
    </geometry>
  </collision>
</link>

<link name="d_part3_1">
  <inertial>
    <origin xyz="-2.5494084521238136e-07 2.479434127455882e-07 -2.3314683517128287e-15" rpy="0 0 0"/>
    <mass value="4.110250388446646e-06"/>
    <inertia ixx="0.0" iyy="0.0" izz="0.0" ixy="0.0" iyz="-0.0" ixz="0.0"/>
  </inertial>
  <visual>
    <origin xyz="-0.294702 -0.255545 -0.0304" rpy="0 0 0"/>
    <geometry>
      <mesh filename="package://spider_robot_description/meshes/d_part3_1.stl" scale="0.001 0.001 0.001"/>
    </geometry>
    <material name="_"/>
  </visual>
  <collision>
    <origin xyz="-0.294702 -0.255545 -0.0304" rpy="0 0 0"/>
    <geometry>
      <mesh filename="package://spider_robot_description/meshes/d_part3_1.stl" scale="0.001 0.001 0.001"/>
    </geometry>
  </collision>
</link>

<link name="d_part4_1">
  <inertial>
    <origin xyz="-2.5494084748833856e-07 -2.4794341335621084e-07 -2.321060010856968e-15" rpy="0 0 0"/>
    <mass value="4.110250388446646e-06"/>
    <inertia ixx="0.0" iyy="0.0" izz="0.0" ixy="0.0" iyz="0.0" ixz="0.0"/>
  </inertial>
  <visual>
    <origin xyz="-0.294702 0.255545 -0.0304" rpy="0 0 0"/>
    <geometry>
      <mesh filename="package://spider_robot_description/meshes/d_part4_1.stl" scale="0.001 0.001 0.001"/>
    </geometry>
    <material name="_"/>
  </visual>
  <collision>
    <origin xyz="-0.294702 0.255545 -0.0304" rpy="0 0 0"/>
    <geometry>
      <mesh filename="package://spider_robot_description/meshes/d_part4_1.stl" scale="0.001 0.001 0.001"/>
    </geometry>
  </collision>
</link>

<link name="d_part5_1">
  <inertial>
    <origin xyz="-2.5494084748833856e-07 -2.4794341335621084e-07 -2.321060010856968e-15" rpy="0 0 0"/>
    <mass value="4.110250388446646e-06"/>
    <inertia ixx="0.0" iyy="0.0" izz="0.0" ixy="0.0" iyz="0.0" ixz="0.0"/>
  </inertial>
  <visual>
    <origin xyz="-0.294702 0.255545 -0.0304" rpy="0 0 0"/>
    <geometry>
      <mesh filename="package://spider_robot_description/meshes/d_part5_1.stl" scale="0.001 0.001 0.001"/>
    </geometry>
    <material name="_"/>
  </visual>
  <collision>
    <origin xyz="-0.294702 0.255545 -0.0304" rpy="0 0 0"/>
    <geometry>
      <mesh filename="package://spider_robot_description/meshes/d_part5_1.stl" scale="0.001 0.001 0.001"/>
    </geometry>
  </collision>
</link>

<link name="d_part6_1">
  <inertial>
    <origin xyz="-2.5494084748833856e-07 -2.4794341335621084e-07 -2.321060010856968e-15" rpy="0 0 0"/>
    <mass value="4.110250388446646e-06"/>
    <inertia ixx="0.0" iyy="0.0" izz="0.0" ixy="0.0" iyz="0.0" ixz="0.0"/>
  </inertial>
  <visual>
    <origin xyz="-0.294702 0.255545 -0.0304" rpy="0 0 0"/>
    <geometry>
      <mesh filename="package://spider_robot_description/meshes/d_part6_1.stl" scale="0.001 0.001 0.001"/>
    </geometry>
    <material name="_"/>
  </visual>
  <collision>
    <origin xyz="-0.294702 0.255545 -0.0304" rpy="0 0 0"/>
    <geometry>
      <mesh filename="package://spider_robot_description/meshes/d_part6_1.stl" scale="0.001 0.001 0.001"/>
    </geometry>
  </collision>
</link>

<link name="d_part7_1">
  <inertial>
    <origin xyz="-4.640385298237959e-17 -8.370776555244319e-08 -2.258609965721803e-15" rpy="0 0 0"/>
    <mass value="4.110250388446646e-06"/>
    <inertia ixx="0.0" iyy="0.0" izz="0.0" ixy="-0.0" iyz="0.0" ixz="-0.0"/>
  </inertial>
  <visual>
    <origin xyz="0.00095 -0.337871 -0.0304" rpy="0 0 0"/>
    <geometry>
      <mesh filename="package://spider_robot_description/meshes/d_part7_1.stl" scale="0.001 0.001 0.001"/>
    </geometry>
    <material name="_"/>
  </visual>
  <collision>
    <origin xyz="0.00095 -0.337871 -0.0304" rpy="0 0 0"/>
    <geometry>
      <mesh filename="package://spider_robot_description/meshes/d_part7_1.stl" scale="0.001 0.001 0.001"/>
    </geometry>
  </collision>
</link>

<link name="d_part8_1">
  <inertial>
    <origin xyz="-4.640385298237959e-17 -8.370776555244319e-08 -2.258609965721803e-15" rpy="0 0 0"/>
    <mass value="4.110250388446646e-06"/>
    <inertia ixx="0.0" iyy="0.0" izz="0.0" ixy="-0.0" iyz="0.0" ixz="-0.0"/>
  </inertial>
  <visual>
    <origin xyz="0.00095 -0.337871 -0.0304" rpy="0 0 0"/>
    <geometry>
      <mesh filename="package://spider_robot_description/meshes/d_part8_1.stl" scale="0.001 0.001 0.001"/>
    </geometry>
    <material name="_"/>
  </visual>
  <collision>
    <origin xyz="0.00095 -0.337871 -0.0304" rpy="0 0 0"/>
    <geometry>
      <mesh filename="package://spider_robot_description/meshes/d_part8_1.stl" scale="0.001 0.001 0.001"/>
    </geometry>
  </collision>
</link>

<link name="d_part9_1">
  <inertial>
    <origin xyz="-4.640385298237959e-17 -8.370776555244319e-08 -2.258609965721803e-15" rpy="0 0 0"/>
    <mass value="4.110250388446646e-06"/>
    <inertia ixx="0.0" iyy="0.0" izz="0.0" ixy="-0.0" iyz="0.0" ixz="-0.0"/>
  </inertial>
  <visual>
    <origin xyz="0.00095 -0.337871 -0.0304" rpy="0 0 0"/>
    <geometry>
      <mesh filename="package://spider_robot_description/meshes/d_part9_1.stl" scale="0.001 0.001 0.001"/>
    </geometry>
    <material name="_"/>
  </visual>
  <collision>
    <origin xyz="0.00095 -0.337871 -0.0304" rpy="0 0 0"/>
    <geometry>
      <mesh filename="package://spider_robot_description/meshes/d_part9_1.stl" scale="0.001 0.001 0.001"/>
    </geometry>
  </collision>
</link>

<link name="d_part10_1">
  <inertial>
    <origin xyz="-2.564354978362715e-15 8.370776855004536e-08 -2.3037127760972e-15" rpy="0 0 0"/>
    <mass value="4.110250388446646e-06"/>
    <inertia ixx="0.0" iyy="0.0" izz="0.0" ixy="0.0" iyz="-0.0" ixz="0.0"/>
  </inertial>
  <visual>
    <origin xyz="0.00095 0.337871 -0.0304" rpy="0 0 0"/>
    <geometry>
      <mesh filename="package://spider_robot_description/meshes/d_part10_1.stl" scale="0.001 0.001 0.001"/>
    </geometry>
    <material name="_"/>
  </visual>
  <collision>
    <origin xyz="0.00095 0.337871 -0.0304" rpy="0 0 0"/>
    <geometry>
      <mesh filename="package://spider_robot_description/meshes/d_part10_1.stl" scale="0.001 0.001 0.001"/>
    </geometry>
  </collision>
</link>

<link name="d_part11_1">
  <inertial>
    <origin xyz="-2.564354978362715e-15 8.370776855004536e-08 -2.3037127760972e-15" rpy="0 0 0"/>
    <mass value="4.110250388446646e-06"/>
    <inertia ixx="0.0" iyy="0.0" izz="0.0" ixy="0.0" iyz="-0.0" ixz="0.0"/>
  </inertial>
  <visual>
    <origin xyz="0.00095 0.337871 -0.0304" rpy="0 0 0"/>
    <geometry>
      <mesh filename="package://spider_robot_description/meshes/d_part11_1.stl" scale="0.001 0.001 0.001"/>
    </geometry>
    <material name="_"/>
  </visual>
  <collision>
    <origin xyz="0.00095 0.337871 -0.0304" rpy="0 0 0"/>
    <geometry>
      <mesh filename="package://spider_robot_description/meshes/d_part11_1.stl" scale="0.001 0.001 0.001"/>
    </geometry>
  </collision>
</link>

<link name="d_part12_1">
  <inertial>
    <origin xyz="-2.564354978362715e-15 8.370776855004536e-08 -2.3037127760972e-15" rpy="0 0 0"/>
    <mass value="4.110250388446646e-06"/>
    <inertia ixx="0.0" iyy="0.0" izz="0.0" ixy="0.0" iyz="-0.0" ixz="0.0"/>
  </inertial>
  <visual>
    <origin xyz="0.00095 0.337871 -0.0304" rpy="0 0 0"/>
    <geometry>
      <mesh filename="package://spider_robot_description/meshes/d_part12_1.stl" scale="0.001 0.001 0.001"/>
    </geometry>
    <material name="_"/>
  </visual>
  <collision>
    <origin xyz="0.00095 0.337871 -0.0304" rpy="0 0 0"/>
    <geometry>
      <mesh filename="package://spider_robot_description/meshes/d_part12_1.stl" scale="0.001 0.001 0.001"/>
    </geometry>
  </collision>
</link>

<link name="d_part13_1">
  <inertial>
    <origin xyz="-2.479434057511831e-07 -2.549408363861083e-07 -2.3002433291452462e-15" rpy="0 0 0"/>
    <mass value="4.110250388446646e-06"/>
    <inertia ixx="0.0" iyy="0.0" izz="0.0" ixy="0.0" iyz="0.0" ixz="0.0"/>
  </inertial>
  <visual>
    <origin xyz="0.296045 -0.254202 -0.0304" rpy="0 0 0"/>
    <geometry>
      <mesh filename="package://spider_robot_description/meshes/d_part13_1.stl" scale="0.001 0.001 0.001"/>
    </geometry>
    <material name="_"/>
  </visual>
  <collision>
    <origin xyz="0.296045 -0.254202 -0.0304" rpy="0 0 0"/>
    <geometry>
      <mesh filename="package://spider_robot_description/meshes/d_part13_1.stl" scale="0.001 0.001 0.001"/>
    </geometry>
  </collision>
</link>

<link name="d_part14_1">
  <inertial>
    <origin xyz="-2.479434057511831e-07 -2.549408363861083e-07 -2.3002433291452462e-15" rpy="0 0 0"/>
    <mass value="4.110250388446646e-06"/>
    <inertia ixx="0.0" iyy="0.0" izz="0.0" ixy="0.0" iyz="0.0" ixz="0.0"/>
  </inertial>
  <visual>
    <origin xyz="0.296045 -0.254202 -0.0304" rpy="0 0 0"/>
    <geometry>
      <mesh filename="package://spider_robot_description/meshes/d_part14_1.stl" scale="0.001 0.001 0.001"/>
    </geometry>
    <material name="_"/>
  </visual>
  <collision>
    <origin xyz="0.296045 -0.254202 -0.0304" rpy="0 0 0"/>
    <geometry>
      <mesh filename="package://spider_robot_description/meshes/d_part14_1.stl" scale="0.001 0.001 0.001"/>
    </geometry>
  </collision>
</link>

<link name="d_part15_1">
  <inertial>
    <origin xyz="-2.479434057511831e-07 -2.549408363861083e-07 -2.3002433291452462e-15" rpy="0 0 0"/>
    <mass value="4.110250388446646e-06"/>
    <inertia ixx="0.0" iyy="0.0" izz="0.0" ixy="0.0" iyz="0.0" ixz="0.0"/>
  </inertial>
  <visual>
    <origin xyz="0.296045 -0.254202 -0.0304" rpy="0 0 0"/>
    <geometry>
      <mesh filename="package://spider_robot_description/meshes/d_part15_1.stl" scale="0.001 0.001 0.001"/>
    </geometry>
    <material name="_"/>
  </visual>
  <collision>
    <origin xyz="0.296045 -0.254202 -0.0304" rpy="0 0 0"/>
    <geometry>
      <mesh filename="package://spider_robot_description/meshes/d_part15_1.stl" scale="0.001 0.001 0.001"/>
    </geometry>
  </collision>
</link>

<link name="d_part16_1">
  <inertial>
    <origin xyz="-2.479434128566105e-07 2.5494084865407274e-07 -2.338407245616736e-15" rpy="0 0 0"/>
    <mass value="4.110250388446646e-06"/>
    <inertia ixx="0.0" iyy="0.0" izz="0.0" ixy="-0.0" iyz="-0.0" ixz="0.0"/>
  </inertial>
  <visual>
    <origin xyz="0.296045 0.254202 -0.0304" rpy="0 0 0"/>
    <geometry>
      <mesh filename="package://spider_robot_description/meshes/d_part16_1.stl" scale="0.001 0.001 0.001"/>
    </geometry>
    <material name="_"/>
  </visual>
  <collision>
    <origin xyz="0.296045 0.254202 -0.0304" rpy="0 0 0"/>
    <geometry>
      <mesh filename="package://spider_robot_description/meshes/d_part16_1.stl" scale="0.001 0.001 0.001"/>
    </geometry>
  </collision>
</link>

<link name="d_part17_1">
  <inertial>
    <origin xyz="-2.479434128566105e-07 2.5494084865407274e-07 -2.338407245616736e-15" rpy="0 0 0"/>
    <mass value="4.110250388446646e-06"/>
    <inertia ixx="0.0" iyy="0.0" izz="0.0" ixy="-0.0" iyz="-0.0" ixz="0.0"/>
  </inertial>
  <visual>
    <origin xyz="0.296045 0.254202 -0.0304" rpy="0 0 0"/>
    <geometry>
      <mesh filename="package://spider_robot_description/meshes/d_part17_1.stl" scale="0.001 0.001 0.001"/>
    </geometry>
    <material name="_"/>
  </visual>
  <collision>
    <origin xyz="0.296045 0.254202 -0.0304" rpy="0 0 0"/>
    <geometry>
      <mesh filename="package://spider_robot_description/meshes/d_part17_1.stl" scale="0.001 0.001 0.001"/>
    </geometry>
  </collision>
</link>

<link name="d_part18_1">
  <inertial>
    <origin xyz="-2.479434128566105e-07 2.5494084865407274e-07 -2.338407245616736e-15" rpy="0 0 0"/>
    <mass value="4.110250388446646e-06"/>
    <inertia ixx="0.0" iyy="0.0" izz="0.0" ixy="-0.0" iyz="-0.0" ixz="0.0"/>
  </inertial>
  <visual>
    <origin xyz="0.296045 0.254202 -0.0304" rpy="0 0 0"/>
    <geometry>
      <mesh filename="package://spider_robot_description/meshes/d_part18_1.stl" scale="0.001 0.001 0.001"/>
    </geometry>
    <material name="_"/>
  </visual>
  <collision>
    <origin xyz="0.296045 0.254202 -0.0304" rpy="0 0 0"/>
    <geometry>
      <mesh filename="package://spider_robot_description/meshes/d_part18_1.stl" scale="0.001 0.001 0.001"/>
    </geometry>
  </collision>
</link>

<link name="body_1">
  <inertial>
    <origin xyz="-0.1080209237916741 -0.04381750881088558 0.07384050386535285" rpy="0 0 0"/>
    <mass value="11.882484155705294"/>
    <inertia ixx="0.03976" iyy="0.086041" izz="0.059318" ixy="-0.000229" iyz="-0.000376" ixz="0.013585"/>
  </inertial>
  <visual>
    <origin xyz="-0.085202 -0.0445 -0.0415" rpy="0 0 0"/>
    <geometry>
      <mesh filename="package://spider_robot_description/meshes/body_1.stl" scale="0.001 0.001 0.001"/>
    </geometry>
    <material name="_"/>
  </visual>
  <collision>
    <origin xyz="-0.085202 -0.0445 -0.0415" rpy="0 0 0"/>
    <geometry>
      <mesh filename="package://spider_robot_description/meshes/body_1.stl" scale="0.001 0.001 0.001"/>
    </geometry>
  </collision>
</link>

<joint name="rev1" type="continuous">
  <origin xyz="0.095 0.0545 0.005" rpy="0 0 0"/>
  <parent link="base_link"/>
  <child link="part1_1"/>
  <axis xyz="-0.0 0.0 -1.0"/>
</joint>

<joint name="rev2" type="continuous">
  <origin xyz="0.02558 0.062173 0.0254" rpy="0 0 0"/>
  <parent link="part1_1"/>
  <child link="part2_1"/>
  <axis xyz="-0.707107 0.707107 -0.0"/>
</joint>

<joint name="rev4" type="continuous">
  <origin xyz="0.095 -0.0545 0.005" rpy="0 0 0"/>
  <parent link="base_link"/>
  <child link="part4_1"/>
  <axis xyz="-0.0 0.0 -1.0"/>
</joint>

<joint name="rev5" type="continuous">
  <origin xyz="0.02558 -0.062173 0.0254" rpy="0 0 0"/>
  <parent link="part4_1"/>
  <child link="part5_1"/>
  <axis xyz="-0.707107 -0.707107 -0.0"/>
</joint>

<joint name="rev7" type="continuous">
  <origin xyz="0.0 0.0545 0.005" rpy="0 0 0"/>
  <parent link="base_link"/>
  <child link="part7_1"/>
  <axis xyz="-0.0 0.0 -1.0"/>
</joint>

<joint name="rev8" type="continuous">
  <origin xyz="-0.025875 0.062051 0.0254" rpy="0 0 0"/>
  <parent link="part7_1"/>
  <child link="part8_1"/>
  <axis xyz="-1.0 0.0 -0.0"/>
</joint>

<joint name="rev10" type="continuous">
  <origin xyz="0.0 -0.0545 0.005" rpy="0 0 0"/>
  <parent link="base_link"/>
  <child link="part10_1"/>
  <axis xyz="-0.0 0.0 -1.0"/>
</joint>

<joint name="rev11" type="continuous">
  <origin xyz="-0.025875 -0.062051 0.0254" rpy="0 0 0"/>
  <parent link="part10_1"/>
  <child link="part11_1"/>
  <axis xyz="-1.0 0.0 -0.0"/>
</joint>

<joint name="rev13" type="continuous">
  <origin xyz="-0.095 0.0545 0.005" rpy="0 0 0"/>
  <parent link="base_link"/>
  <child link="part13_1"/>
  <axis xyz="-0.0 0.0 -1.0"/>
</joint>

<joint name="rev14" type="continuous">
  <origin xyz="-0.062173 0.02558 0.0254" rpy="0 0 0"/>
  <parent link="part13_1"/>
  <child link="part14_1"/>
  <axis xyz="-0.707107 -0.707107 -0.0"/>
</joint>

<joint name="rev16" type="continuous">
  <origin xyz="-0.095 -0.0545 0.005" rpy="0 0 0"/>
  <parent link="base_link"/>
  <child link="part16_1"/>
  <axis xyz="-0.0 0.0 -1.0"/>
</joint>

<joint name="rev17" type="continuous">
  <origin xyz="-0.062173 -0.02558 0.0254" rpy="0 0 0"/>
  <parent link="part16_1"/>
  <child link="part17_1"/>
  <axis xyz="-0.707107 0.707107 0.0"/>
</joint>

<joint name="rev3" type="continuous">
  <origin xyz="0.093423 0.021581 0.0" rpy="0 0 0"/>
  <parent link="part2_1"/>
  <child link="part3_1"/>
  <axis xyz="-0.707107 0.707107 -0.0"/>
</joint>

<joint name="rev6" type="continuous">
  <origin xyz="0.093423 -0.021581 0.0" rpy="0 0 0"/>
  <parent link="part5_1"/>
  <child link="part6_1"/>
  <axis xyz="-0.707107 -0.707107 -0.0"/>
</joint>

<joint name="rev9" type="continuous">
  <origin xyz="0.0508 0.08132 0.0" rpy="0 0 0"/>
  <parent link="part8_1"/>
  <child link="part9_1"/>
  <axis xyz="-1.0 -0.0 -0.0"/>
</joint>

<joint name="rev12" type="continuous">
  <origin xyz="0.0508 -0.08132 0.0" rpy="0 0 0"/>
  <parent link="part11_1"/>
  <child link="part12_1"/>
  <axis xyz="-1.0 0.0 -0.0"/>
</joint>

<joint name="rev15" type="continuous">
  <origin xyz="-0.021581 0.093423 0.0" rpy="0 0 0"/>
  <parent link="part14_1"/>
  <child link="part15_1"/>
  <axis xyz="-0.707107 -0.707107 -0.0"/>
</joint>

<joint name="rev18" type="continuous">
  <origin xyz="-0.021581 -0.093423 0.0" rpy="0 0 0"/>
  <parent link="part17_1"/>
  <child link="part18_1"/>
  <axis xyz="-0.707107 0.707107 0.0"/>
</joint>

<joint name="d_rev1" type="continuous">
  <origin xyz="0.080699 0.117291 0.0" rpy="0 0 0"/>
  <parent link="part3_1"/>
  <child link="d_part1_1"/>
  <axis xyz="0.707107 0.707107 -0.0"/>
</joint>

<joint name="d_rev2" type="continuous">
  <origin xyz="0.0 0.0 0.0" rpy="0 0 0"/>
  <parent link="d_part1_1"/>
  <child link="d_part2_1"/>
  <axis xyz="0.707107 -0.707107 0.0"/>
</joint>

<joint name="d_rev3" type="continuous">
  <origin xyz="0.0 0.0 0.0" rpy="0 0 0"/>
  <parent link="d_part2_1"/>
  <child link="d_part3_1"/>
  <axis xyz="0.0 0.0 1.0"/>
</joint>

<joint name="d_rev4" type="continuous">
  <origin xyz="0.080699 -0.117291 0.0" rpy="0 0 0"/>
  <parent link="part6_1"/>
  <child link="d_part4_1"/>
  <axis xyz="0.707107 -0.707107 -0.0"/>
</joint>

<joint name="d_rev5" type="continuous">
  <origin xyz="0.0 0.0 0.0" rpy="0 0 0"/>
  <parent link="d_part4_1"/>
  <child link="d_part5_1"/>
  <axis xyz="-0.707107 -0.707107 -0.0"/>
</joint>

<joint name="d_rev6" type="continuous">
  <origin xyz="0.0 0.0 0.0" rpy="0 0 0"/>
  <parent link="d_part5_1"/>
  <child link="d_part6_1"/>
  <axis xyz="0.0 -0.0 1.0"/>
</joint>

<joint name="d_rev7" type="continuous">
  <origin xyz="-0.025875 0.14 0.0" rpy="0 0 0"/>
  <parent link="part9_1"/>
  <child link="d_part7_1"/>
  <axis xyz="-0.0 1.0 -0.0"/>
</joint>

<joint name="d_rev8" type="continuous">
  <origin xyz="0.0 0.0 0.0" rpy="0 0 0"/>
  <parent link="d_part7_1"/>
  <child link="d_part8_1"/>
  <axis xyz="1.0 0.0 0.0"/>
</joint>

<joint name="d_rev9" type="continuous">
  <origin xyz="0.0 0.0 0.0" rpy="0 0 0"/>
  <parent link="d_part8_1"/>
  <child link="d_part9_1"/>
  <axis xyz="-0.0 0.0 1.0"/>
</joint>

<joint name="d_rev10" type="continuous">
  <origin xyz="-0.025875 -0.14 0.0" rpy="0 0 0"/>
  <parent link="part12_1"/>
  <child link="d_part10_1"/>
  <axis xyz="-0.0 -1.0 -0.0"/>
</joint>

<joint name="d_rev11" type="continuous">
  <origin xyz="0.0 0.0 0.0" rpy="0 0 0"/>
  <parent link="d_part10_1"/>
  <child link="d_part11_1"/>
  <axis xyz="-1.0 0.0 -0.0"/>
</joint>

<joint name="d_rev12" type="continuous">
  <origin xyz="0.0 0.0 0.0" rpy="0 0 0"/>
  <parent link="d_part11_1"/>
  <child link="d_part12_1"/>
  <axis xyz="-0.0 -0.0 1.0"/>
</joint>

<joint name="d_rev13" type="continuous">
  <origin xyz="-0.117291 0.080699 0.0" rpy="0 0 0"/>
  <parent link="part15_1"/>
  <child link="d_part13_1"/>
  <axis xyz="-0.707107 0.707107 -0.0"/>
</joint>

<joint name="d_rev14" type="continuous">
  <origin xyz="0.0 0.0 0.0" rpy="0 0 0"/>
  <parent link="d_part13_1"/>
  <child link="d_part14_1"/>
  <axis xyz="0.707107 0.707107 0.0"/>
</joint>

<joint name="d_rev15" type="continuous">
  <origin xyz="0.0 0.0 0.0" rpy="0 0 0"/>
  <parent link="d_part14_1"/>
  <child link="d_part15_1"/>
  <axis xyz="-0.0 0.0 1.0"/>
</joint>

<joint name="d_rev16" type="continuous">
  <origin xyz="-0.117291 -0.080699 0.0" rpy="0 0 0"/>
  <parent link="part18_1"/>
  <child link="d_part16_1"/>
  <axis xyz="-0.707107 -0.707107 -0.0"/>
</joint>

<joint name="d_rev17" type="continuous">
  <origin xyz="0.0 0.0 0.0" rpy="0 0 0"/>
  <parent link="part18_1"/>
  <child link="d_part17_1"/>
  <axis xyz="-0.707107 0.707107 0.0"/>
</joint>

<joint name="d_rev18" type="continuous">
  <origin xyz="0.0 0.0 0.0" rpy="0 0 0"/>
  <parent link="part18_1"/>
  <child link="d_part18_1"/>
  <axis xyz="-0.0 -0.0 1.0"/>
</joint>

<joint name="fix1" type="fixed">
  <origin xyz="0.085202 0.0445 0.0415" rpy="0 0 0"/>
  <parent link="base_link"/>
  <child link="body_1"/>
</joint>

</robot>
